Workbook
Name AgeOfElectrical: Lists!$A$32:$A$35
Name AgeOfHVAC: Lists!$C$32:$C$35
Name AgeOfPlumbing: Lists!$K$2:$K$5
Name CentralFireAlarm: Lists!$M$32:$M$33
Name Circuits: Lists!$L$2:$L$5
Name CoastalOptions: Lists!$S$32:$S$33
Name Ctype: Lists!$F$2:$F$7
Name FreezerSensors: Lists!$L$32:$L$34
Name HailClaims: Lists!$R$32:$R$34
Name HeatingType: Lists!$B$32:$B$41
Name IntCovOptions: Lists!$E$32:$E$36
Name LocationBlanketLimit: Lists!$P$32:$P$33
Name LossSettlement: Lists!$Q$32:$Q$33
Name OwnershipOptions: Lists!$A$4:$A$6
Name PctLeased: Lists!$F$32:$F$41
Name PctOcc: Lists!$G$32:$G$34
Name ProtClassOptions: Lists!$H$2:$H$11
Name RoofShapeOptions: Lists!$J$2:$J$6
Name RoofType: Lists!$I$2:$I$9
Name SCOptions: Lists!$N$32:$N$33
Name SmokeDetectors: Lists!$I$32:$I$35
Name SmokingOptions: Lists!$J$32:$J$34
Name SprinkLeakExcl: Lists!$O$32:$O$33
Name SprinklerSystem: Lists!$H$32:$H$34
Name StovetopFSOptions: Lists!$K$32:$K$34
Name UnderRenovation: Lists!$D$32:$D$33
Name WiringType: Lists!$M$2:$M$5
Name WiringUpdate: Lists!$N$2:$N$5
Name ZipCodeText: ZipCodes!$A$1:$C$15451

Sheet SOV
M1: LIMITS | Q1: BUILDING FEATURES | AG1: OCCUPANCY | AK1: SQUARE FOOTAGE | AL1: PROTECTION | AS1: VALUES AND COVERAGES
A2: Loc # | B2: Bldg # | C2: Complex Name | D2: Address | E2: City | F2: State | G2: Zip Code | H2: County | I2: Ownership | J2: Primary Class | K2: Secondary Class | L2: % Secondary Class | M2: Building Value | N2: Contents Value | O2: Association Income | P2: TIV | Q2: Construction Type | R2: Protection Class | S2: Number of Buildings | T2: # of Stories | U2: Year Built | V2: Year of Roof Update | W2: Roof Type | X2: Roof Shape | Y2: Age of Plumbing | Z2: Circuit Breakers/ Fuses | AA2: Wiring type | AB2: Wiring Update Type if Aluminum | AC2: Age of Electrical | AD2: Heating type | AE2: Age of HVAC | AF2: Under Renovation | AG2: # of Units | AH2: Condo Association Interior Coverage | AI2: Condo Assocation % Units Rented | AJ2: % Occupied (or will be within 60 days with COO) | AK2: Above Ground Sq.Ft. | AL2: Sprinkler Protection | AM2: Smoke Detectors | AN2: Smoking Restriction | AO2: Stovetop Suppression Device | AP2: Water/Freeze Sensors | AQ2: Central Station Fire Alarm | AR2: Surveillance Camera | AS2: Sprinkler Leakage Exclusion | AT2: Location Blanket Limit | AU2: Loss Settlement | AV2: Open Hail Claims | AW2: Within 2500 Feet of Coastline (if in Windzone and blank assumes coastal) | AX2: Additional Property Covered | AY2: Additional Property Not Covered | AZ2: Primary Class
F3: =IF(G3="","",VLOOKUP(TEXT(G3, "00000"),ZipCodeText,3,FALSE)) -> CT | G3: 6540 | P3: =IF(G3="","",SUM(M3:O3)) -> 0 | AZ3: =IF($G3="","",IF($I3=Lists!$B$4,Lists!$B$4,Lists!$C$4)) -> Club House | BA3: =IF($G3="","",IF($I3=Lists!$B$4,Lists!$B$5,Lists!$C$5)) -> Mercantile | BB3: =IF($G3="","",IF($I3=Lists!$B$4,Lists!$B$6,Lists!$C$6)) -> Office | BC3: =IF($G3="","",IF($I3=Lists!$B$5,Lists!$B$7,Lists!$C$7)) -> Outbuilding | BD3: =IF($G3="","",IF($I3=Lists!$B$4,Lists!$B$8,Lists!$C$8)) -> Parking Garage | BE3: =IF($G3="","",IF($I3=Lists!$B$4,Lists!$B$9,Lists!$C$9)) -> Primary Residential Association | BF3: =IF($G3="","",IF($I3=Lists!$B$4,Lists!$B$10,Lists!$C$10)) -> Restaurant | BG3: =IF($G3="","",IF($I3=Lists!$B$4,Lists!$B$11,Lists!$C$11)) -> Secondary Residential Association | BH3: =IF($G3="","",IF($I3=Lists!$B$4,Lists!$B$12,Lists!$C$12)) -> Timeshare Association | BI3: =IF($G3="","",IF($I3=Lists!$B$4,Lists!$B$13,Lists!$C$13)) -> Detached Garages | BJ3: =IF($G3="","",IF($I3=Lists!$B$4,Lists!$B$14,Lists!$C$14)) -> Pool | BK3: =IF($G3="","",IF($I3=Lists!$B$4,Lists!$B$15,Lists!$C$15)) -> Street Lights | BL3: =IF($G3="","",IF($I3=Lists!$B$4,Lists!$B$16,Lists!$C$16)) -> Fence | BM3: =IF($G3="","",IF($I3=Lists!$B$4,Lists!$B$17,Lists!$C$17)) -> Docks | BN3: =IF($G3="","",IF($I3=Lists!$B$4,Lists!$B$18,Lists!$C$18)) -> Sign | BO3: =IF($G3="","",IF($I3=Lists!$B$4,Lists!$B$19,Lists!$C$19)) -> Other | BP3: =IF($G3="","",IF($I3=Lists!$B$4,Lists!$C$20,"")) | BQ3: =IF($G3="","",IF($I3=Lists!$B$4,Lists!$C$21,"")) | BR3: =IF($G3="","",IF($I3=Lists!$B$4,Lists!$C$22,"")) | BS3: =IF($G3="","",IF($I3=Lists!$B$4,Lists!$C$23,"")) | BT3: =IF($G3="","",IF($I3=Lists!$B$4,Lists!$C$24,"")) | BU3: =IF($G3="","",IF($I3=Lists!$B$4,Lists!$C$25,"")) | BV3: =IF($G3="","",IF($I3=Lists!$B$4,Lists!$C$26,"")) | BW3: =IF($G3="","",IF($I3=Lists!$B$4,Lists!$C$27,""))
F4: =IF(G4="","",VLOOKUP(TEXT(G4, "00000"),ZipCodeText,3,FALSE)) -> CT | G4: 6226 | P4: =IF(G4="","",SUM(M4:O4)) -> 0 | AZ4: =IF($G4="","",IF($I4=Lists!$B$4,Lists!$B$4,Lists!$C$4)) -> Club House | BA4: =IF($G4="","",IF($I4=Lists!$B$4,Lists!$B$5,Lists!$C$5)) -> Mercantile | BB4: =IF($G4="","",IF($I4=Lists!$B$4,Lists!$B$6,Lists!$C$6)) -> Office | BC4: =IF($G4="","",IF($I4=Lists!$B$5,Lists!$B$7,Lists!$C$7)) -> Outbuilding | BD4: =IF($G4="","",IF($I4=Lists!$B$4,Lists!$B$8,Lists!$C$8)) -> Parking Garage | BE4: =IF($G4="","",IF($I4=Lists!$B$4,Lists!$B$9,Lists!$C$9)) -> Primary Residential Association | BF4: =IF($G4="","",IF($I4=Lists!$B$4,Lists!$B$10,Lists!$C$10)) -> Restaurant | BG4: =IF($G4="","",IF($I4=Lists!$B$4,Lists!$B$11,Lists!$C$11)) -> Secondary Residential Association | BH4: =IF($G4="","",IF($I4=Lists!$B$4,Lists!$B$12,Lists!$C$12)) -> Timeshare Association | BI4: =IF($G4="","",IF($I4=Lists!$B$4,Lists!$B$13,Lists!$C$13)) -> Detached Garages | BJ4: =IF($G4="","",IF($I4=Lists!$B$4,Lists!$B$14,Lists!$C$14)) -> Pool | BK4: =IF($G4="","",IF($I4=Lists!$B$4,Lists!$B$15,Lists!$C$15)) -> Street Lights | BL4: =IF($G4="","",IF($I4=Lists!$B$4,Lists!$B$16,Lists!$C$16)) -> Fence | BM4: =IF($G4="","",IF($I4=Lists!$B$4,Lists!$B$17,Lists!$C$17)) -> Docks | BN4: =IF($G4="","",IF($I4=Lists!$B$4,Lists!$B$18,Lists!$C$18)) -> Sign | BO4: =IF($G4="","",IF($I4=Lists!$B$4,Lists!$B$19,Lists!$C$19)) -> Other | BP4: =IF($G4="","",IF($I4=Lists!$B$4,Lists!$C$20,"")) | BQ4: =IF($G4="","",IF($I4=Lists!$B$4,Lists!$C$21,"")) | BR4: =IF($G4="","",IF($I4=Lists!$B$4,Lists!$C$22,"")) | BS4: =IF($G4="","",IF($I4=Lists!$B$4,Lists!$C$23,"")) | BT4: =IF($G4="","",IF($I4=Lists!$B$4,Lists!$C$24,"")) | BU4: =IF($G4="","",IF($I4=Lists!$B$4,Lists!$C$25,"")) | BV4: =IF($G4="","",IF($I4=Lists!$B$4,Lists!$C$26,"")) | BW4: =IF($G4="","",IF($I4=Lists!$B$4,Lists!$C$27,""))
D5: ` | F5: =IF(G5="","",VLOOKUP(TEXT(G5, "00000"),ZipCodeText,3,FALSE)) -> CT | G5: 6226 | P5: =IF(G5="","",SUM(M5:O5)) -> 0 | AZ5: =IF($G5="","",IF($I5=Lists!$B$4,Lists!$B$4,Lists!$C$4)) -> Club House | BA5: =IF($G5="","",IF($I5=Lists!$B$4,Lists!$B$5,Lists!$C$5)) -> Mercantile | BB5: =IF($G5="","",IF($I5=Lists!$B$4,Lists!$B$6,Lists!$C$6)) -> Office | BC5: =IF($G5="","",IF($I5=Lists!$B$5,Lists!$B$7,Lists!$C$7)) -> Outbuilding | BD5: =IF($G5="","",IF($I5=Lists!$B$4,Lists!$B$8,Lists!$C$8)) -> Parking Garage | BE5: =IF($G5="","",IF($I5=Lists!$B$4,Lists!$B$9,Lists!$C$9)) -> Primary Residential Association | BF5: =IF($G5="","",IF($I5=Lists!$B$4,Lists!$B$10,Lists!$C$10)) -> Restaurant | BG5: =IF($G5="","",IF($I5=Lists!$B$4,Lists!$B$11,Lists!$C$11)) -> Secondary Residential Association | BH5: =IF($G5="","",IF($I5=Lists!$B$4,Lists!$B$12,Lists!$C$12)) -> Timeshare Association | BI5: =IF($G5="","",IF($I5=Lists!$B$4,Lists!$B$13,Lists!$C$13)) -> Detached Garages | BJ5: =IF($G5="","",IF($I5=Lists!$B$4,Lists!$B$14,Lists!$C$14)) -> Pool | BK5: =IF($G5="","",IF($I5=Lists!$B$4,Lists!$B$15,Lists!$C$15)) -> Street Lights | BL5: =IF($G5="","",IF($I5=Lists!$B$4,Lists!$B$16,Lists!$C$16)) -> Fence | BM5: =IF($G5="","",IF($I5=Lists!$B$4,Lists!$B$17,Lists!$C$17)) -> Docks | BN5: =IF($G5="","",IF($I5=Lists!$B$4,Lists!$B$18,Lists!$C$18)) -> Sign | BO5: =IF($G5="","",IF($I5=Lists!$B$4,Lists!$B$19,Lists!$C$19)) -> Other | BP5: =IF($G5="","",IF($I5=Lists!$B$4,Lists!$C$20,"")) | BQ5: =IF($G5="","",IF($I5=Lists!$B$4,Lists!$C$21,"")) | BR5: =IF($G5="","",IF($I5=Lists!$B$4,Lists!$C$22,"")) | BS5: =IF($G5="","",IF($I5=Lists!$B$4,Lists!$C$23,"")) | BT5: =IF($G5="","",IF($I5=Lists!$B$4,Lists!$C$24,"")) | BU5: =IF($G5="","",IF($I5=Lists!$B$4,Lists!$C$25,"")) | BV5: =IF($G5="","",IF($I5=Lists!$B$4,Lists!$C$26,"")) | BW5: =IF($G5="","",IF($I5=Lists!$B$4,Lists!$C$27,""))
F6: =IF(G6="","",VLOOKUP(TEXT(G6, "00000"),ZipCodeText,3,FALSE)) -> CT | G6: 6226 | P6: =IF(G6="","",SUM(M6:O6)) -> 0 | AZ6: =IF($G6="","",IF($I6=Lists!$B$4,Lists!$B$4,Lists!$C$4)) -> Club House | BA6: =IF($G6="","",IF($I6=Lists!$B$4,Lists!$B$5,Lists!$C$5)) -> Mercantile | BB6: =IF($G6="","",IF($I6=Lists!$B$4,Lists!$B$6,Lists!$C$6)) -> Office | BC6: =IF($G6="","",IF($I6=Lists!$B$5,Lists!$B$7,Lists!$C$7)) -> Outbuilding | BD6: =IF($G6="","",IF($I6=Lists!$B$4,Lists!$B$8,Lists!$C$8)) -> Parking Garage | BE6: =IF($G6="","",IF($I6=Lists!$B$4,Lists!$B$9,Lists!$C$9)) -> Primary Residential Association | BF6: =IF($G6="","",IF($I6=Lists!$B$4,Lists!$B$10,Lists!$C$10)) -> Restaurant | BG6: =IF($G6="","",IF($I6=Lists!$B$4,Lists!$B$11,Lists!$C$11)) -> Secondary Residential Association | BH6: =IF($G6="","",IF($I6=Lists!$B$4,Lists!$B$12,Lists!$C$12)) -> Timeshare Association | BI6: =IF($G6="","",IF($I6=Lists!$B$4,Lists!$B$13,Lists!$C$13)) -> Detached Garages | BJ6: =IF($G6="","",IF($I6=Lists!$B$4,Lists!$B$14,Lists!$C$14)) -> Pool | BK6: =IF($G6="","",IF($I6=Lists!$B$4,Lists!$B$15,Lists!$C$15)) -> Street Lights | BL6: =IF($G6="","",IF($I6=Lists!$B$4,Lists!$B$16,Lists!$C$16)) -> Fence | BM6: =IF($G6="","",IF($I6=Lists!$B$4,Lists!$B$17,Lists!$C$17)) -> Docks | BN6: =IF($G6="","",IF($I6=Lists!$B$4,Lists!$B$18,Lists!$C$18)) -> Sign | BO6: =IF($G6="","",IF($I6=Lists!$B$4,Lists!$B$19,Lists!$C$19)) -> Other | BP6: =IF($G6="","",IF($I6=Lists!$B$4,Lists!$C$20,"")) | BQ6: =IF($G6="","",IF($I6=Lists!$B$4,Lists!$C$21,"")) | BR6: =IF($G6="","",IF($I6=Lists!$B$4,Lists!$C$22,"")) | BS6: =IF($G6="","",IF($I6=Lists!$B$4,Lists!$C$23,"")) | BT6: =IF($G6="","",IF($I6=Lists!$B$4,Lists!$C$24,"")) | BU6: =IF($G6="","",IF($I6=Lists!$B$4,Lists!$C$25,"")) | BV6: =IF($G6="","",IF($I6=Lists!$B$4,Lists!$C$26,"")) | BW6: =IF($G6="","",IF($I6=Lists!$B$4,Lists!$C$27,""))
F7: =IF(G7="","",VLOOKUP(TEXT(G7, "00000"),ZipCodeText,3,FALSE)) -> CT | G7: 6226 | P7: =IF(G7="","",SUM(M7:O7)) -> 0 | AZ7: =IF($G7="","",IF($I7=Lists!$B$4,Lists!$B$4,Lists!$C$4)) -> Club House | BA7: =IF($G7="","",IF($I7=Lists!$B$4,Lists!$B$5,Lists!$C$5)) -> Mercantile | BB7: =IF($G7="","",IF($I7=Lists!$B$4,Lists!$B$6,Lists!$C$6)) -> Office | BC7: =IF($G7="","",IF($I7=Lists!$B$5,Lists!$B$7,Lists!$C$7)) -> Outbuilding | BD7: =IF($G7="","",IF($I7=Lists!$B$4,Lists!$B$8,Lists!$C$8)) -> Parking Garage | BE7: =IF($G7="","",IF($I7=Lists!$B$4,Lists!$B$9,Lists!$C$9)) -> Primary Residential Association | BF7: =IF($G7="","",IF($I7=Lists!$B$4,Lists!$B$10,Lists!$C$10)) -> Restaurant | BG7: =IF($G7="","",IF($I7=Lists!$B$4,Lists!$B$11,Lists!$C$11)) -> Secondary Residential Association | BH7: =IF($G7="","",IF($I7=Lists!$B$4,Lists!$B$12,Lists!$C$12)) -> Timeshare Association | BI7: =IF($G7="","",IF($I7=Lists!$B$4,Lists!$B$13,Lists!$C$13)) -> Detached Garages | BJ7: =IF($G7="","",IF($I7=Lists!$B$4,Lists!$B$14,Lists!$C$14)) -> Pool | BK7: =IF($G7="","",IF($I7=Lists!$B$4,Lists!$B$15,Lists!$C$15)) -> Street Lights | BL7: =IF($G7="","",IF($I7=Lists!$B$4,Lists!$B$16,Lists!$C$16)) -> Fence | BM7: =IF($G7="","",IF($I7=Lists!$B$4,Lists!$B$17,Lists!$C$17)) -> Docks | BN7: =IF($G7="","",IF($I7=Lists!$B$4,Lists!$B$18,Lists!$C$18)) -> Sign | BO7: =IF($G7="","",IF($I7=Lists!$B$4,Lists!$B$19,Lists!$C$19)) -> Other | BP7: =IF($G7="","",IF($I7=Lists!$B$4,Lists!$C$20,"")) | BQ7: =IF($G7="","",IF($I7=Lists!$B$4,Lists!$C$21,"")) | BR7: =IF($G7="","",IF($I7=Lists!$B$4,Lists!$C$22,"")) | BS7: =IF($G7="","",IF($I7=Lists!$B$4,Lists!$C$23,"")) | BT7: =IF($G7="","",IF($I7=Lists!$B$4,Lists!$C$24,"")) | BU7: =IF($G7="","",IF($I7=Lists!$B$4,Lists!$C$25,"")) | BV7: =IF($G7="","",IF($I7=Lists!$B$4,Lists!$C$26,"")) | BW7: =IF($G7="","",IF($I7=Lists!$B$4,Lists!$C$27,""))
F8: =IF(G8="","",VLOOKUP(TEXT(G8, "00000"),ZipCodeText,3,FALSE)) -> CT | G8: 6226 | P8: =IF(G8="","",SUM(M8:O8)) -> 0 | AZ8: =IF($G8="","",IF($I8=Lists!$B$4,Lists!$B$4,Lists!$C$4)) -> Club House | BA8: =IF($G8="","",IF($I8=Lists!$B$4,Lists!$B$5,Lists!$C$5)) -> Mercantile | BB8: =IF($G8="","",IF($I8=Lists!$B$4,Lists!$B$6,Lists!$C$6)) -> Office | BC8: =IF($G8="","",IF($I8=Lists!$B$5,Lists!$B$7,Lists!$C$7)) -> Outbuilding | BD8: =IF($G8="","",IF($I8=Lists!$B$4,Lists!$B$8,Lists!$C$8)) -> Parking Garage | BE8: =IF($G8="","",IF($I8=Lists!$B$4,Lists!$B$9,Lists!$C$9)) -> Primary Residential Association | BF8: =IF($G8="","",IF($I8=Lists!$B$4,Lists!$B$10,Lists!$C$10)) -> Restaurant | BG8: =IF($G8="","",IF($I8=Lists!$B$4,Lists!$B$11,Lists!$C$11)) -> Secondary Residential Association | BH8: =IF($G8="","",IF($I8=Lists!$B$4,Lists!$B$12,Lists!$C$12)) -> Timeshare Association | BI8: =IF($G8="","",IF($I8=Lists!$B$4,Lists!$B$13,Lists!$C$13)) -> Detached Garages | BJ8: =IF($G8="","",IF($I8=Lists!$B$4,Lists!$B$14,Lists!$C$14)) -> Pool | BK8: =IF($G8="","",IF($I8=Lists!$B$4,Lists!$B$15,Lists!$C$15)) -> Street Lights | BL8: =IF($G8="","",IF($I8=Lists!$B$4,Lists!$B$16,Lists!$C$16)) -> Fence | BM8: =IF($G8="","",IF($I8=Lists!$B$4,Lists!$B$17,Lists!$C$17)) -> Docks | BN8: =IF($G8="","",IF($I8=Lists!$B$4,Lists!$B$18,Lists!$C$18)) -> Sign | BO8: =IF($G8="","",IF($I8=Lists!$B$4,Lists!$B$19,Lists!$C$19)) -> Other | BP8: =IF($G8="","",IF($I8=Lists!$B$4,Lists!$C$20,"")) | BQ8: =IF($G8="","",IF($I8=Lists!$B$4,Lists!$C$21,"")) | BR8: =IF($G8="","",IF($I8=Lists!$B$4,Lists!$C$22,"")) | BS8: =IF($G8="","",IF($I8=Lists!$B$4,Lists!$C$23,"")) | BT8: =IF($G8="","",IF($I8=Lists!$B$4,Lists!$C$24,"")) | BU8: =IF($G8="","",IF($I8=Lists!$B$4,Lists!$C$25,"")) | BV8: =IF($G8="","",IF($I8=Lists!$B$4,Lists!$C$26,"")) | BW8: =IF($G8="","",IF($I8=Lists!$B$4,Lists!$C$27,""))
F9: =IF(G9="","",VLOOKUP(TEXT(G9, "00000"),ZipCodeText,3,FALSE)) -> CT | G9: 6226 | P9: =IF(G9="","",SUM(M9:O9)) -> 0 | AZ9: =IF($G9="","",IF($I9=Lists!$B$4,Lists!$B$4,Lists!$C$4)) -> Club House | BA9: =IF($G9="","",IF($I9=Lists!$B$4,Lists!$B$5,Lists!$C$5)) -> Mercantile | BB9: =IF($G9="","",IF($I9=Lists!$B$4,Lists!$B$6,Lists!$C$6)) -> Office | BC9: =IF($G9="","",IF($I9=Lists!$B$5,Lists!$B$7,Lists!$C$7)) -> Outbuilding | BD9: =IF($G9="","",IF($I9=Lists!$B$4,Lists!$B$8,Lists!$C$8)) -> Parking Garage | BE9: =IF($G9="","",IF($I9=Lists!$B$4,Lists!$B$9,Lists!$C$9)) -> Primary Residential Association | BF9: =IF($G9="","",IF($I9=Lists!$B$4,Lists!$B$10,Lists!$C$10)) -> Restaurant | BG9: =IF($G9="","",IF($I9=Lists!$B$4,Lists!$B$11,Lists!$C$11)) -> Secondary Residential Association | BH9: =IF($G9="","",IF($I9=Lists!$B$4,Lists!$B$12,Lists!$C$12)) -> Timeshare Association | BI9: =IF($G9="","",IF($I9=Lists!$B$4,Lists!$B$13,Lists!$C$13)) -> Detached Garages | BJ9: =IF($G9="","",IF($I9=Lists!$B$4,Lists!$B$14,Lists!$C$14)) -> Pool | BK9: =IF($G9="","",IF($I9=Lists!$B$4,Lists!$B$15,Lists!$C$15)) -> Street Lights | BL9: =IF($G9="","",IF($I9=Lists!$B$4,Lists!$B$16,Lists!$C$16)) -> Fence | BM9: =IF($G9="","",IF($I9=Lists!$B$4,Lists!$B$17,Lists!$C$17)) -> Docks | BN9: =IF($G9="","",IF($I9=Lists!$B$4,Lists!$B$18,Lists!$C$18)) -> Sign | BO9: =IF($G9="","",IF($I9=Lists!$B$4,Lists!$B$19,Lists!$C$19)) -> Other | BP9: =IF($G9="","",IF($I9=Lists!$B$4,Lists!$C$20,"")) | BQ9: =IF($G9="","",IF($I9=Lists!$B$4,Lists!$C$21,"")) | BR9: =IF($G9="","",IF($I9=Lists!$B$4,Lists!$C$22,"")) | BS9: =IF($G9="","",IF($I9=Lists!$B$4,Lists!$C$23,"")) | BT9: =IF($G9="","",IF($I9=Lists!$B$4,Lists!$C$24,"")) | BU9: =IF($G9="","",IF($I9=Lists!$B$4,Lists!$C$25,"")) | BV9: =IF($G9="","",IF($I9=Lists!$B$4,Lists!$C$26,"")) | BW9: =IF($G9="","",IF($I9=Lists!$B$4,Lists!$C$27,""))
F10: =IF(G10="","",VLOOKUP(TEXT(G10, "00000"),ZipCodeText,3,FALSE)) -> CT | G10: 6226 | P10: =IF(G10="","",SUM(M10:O10)) -> 0 | AZ10: =IF($G10="","",IF($I10=Lists!$B$4,Lists!$B$4,Lists!$C$4)) -> Club House | BA10: =IF($G10="","",IF($I10=Lists!$B$4,Lists!$B$5,Lists!$C$5)) -> Mercantile | BB10: =IF($G10="","",IF($I10=Lists!$B$4,Lists!$B$6,Lists!$C$6)) -> Office | BC10: =IF($G10="","",IF($I10=Lists!$B$5,Lists!$B$7,Lists!$C$7)) -> Outbuilding | BD10: =IF($G10="","",IF($I10=Lists!$B$4,Lists!$B$8,Lists!$C$8)) -> Parking Garage | BE10: =IF($G10="","",IF($I10=Lists!$B$4,Lists!$B$9,Lists!$C$9)) -> Primary Residential Association | BF10: =IF($G10="","",IF($I10=Lists!$B$4,Lists!$B$10,Lists!$C$10)) -> Restaurant | BG10: =IF($G10="","",IF($I10=Lists!$B$4,Lists!$B$11,Lists!$C$11)) -> Secondary Residential Association | BH10: =IF($G10="","",IF($I10=Lists!$B$4,Lists!$B$12,Lists!$C$12)) -> Timeshare Association | BI10: =IF($G10="","",IF($I10=Lists!$B$4,Lists!$B$13,Lists!$C$13)) -> Detached Garages | BJ10: =IF($G10="","",IF($I10=Lists!$B$4,Lists!$B$14,Lists!$C$14)) -> Pool | BK10: =IF($G10="","",IF($I10=Lists!$B$4,Lists!$B$15,Lists!$C$15)) -> Street Lights | BL10: =IF($G10="","",IF($I10=Lists!$B$4,Lists!$B$16,Lists!$C$16)) -> Fence | BM10: =IF($G10="","",IF($I10=Lists!$B$4,Lists!$B$17,Lists!$C$17)) -> Docks | BN10: =IF($G10="","",IF($I10=Lists!$B$4,Lists!$B$18,Lists!$C$18)) -> Sign | BO10: =IF($G10="","",IF($I10=Lists!$B$4,Lists!$B$19,Lists!$C$19)) -> Other | BP10: =IF($G10="","",IF($I10=Lists!$B$4,Lists!$C$20,"")) | BQ10: =IF($G10="","",IF($I10=Lists!$B$4,Lists!$C$21,"")) | BR10: =IF($G10="","",IF($I10=Lists!$B$4,Lists!$C$22,"")) | BS10: =IF($G10="","",IF($I10=Lists!$B$4,Lists!$C$23,"")) | BT10: =IF($G10="","",IF($I10=Lists!$B$4,Lists!$C$24,"")) | BU10: =IF($G10="","",IF($I10=Lists!$B$4,Lists!$C$25,"")) | BV10: =IF($G10="","",IF($I10=Lists!$B$4,Lists!$C$26,"")) | BW10: =IF($G10="","",IF($I10=Lists!$B$4,Lists!$C$27,""))
F11: =IF(G11="","",VLOOKUP(TEXT(G11, "00000"),ZipCodeText,3,FALSE)) -> CT | G11: 6226 | P11: =IF(G11="","",SUM(M11:O11)) -> 0 | AZ11: =IF($G11="","",IF($I11=Lists!$B$4,Lists!$B$4,Lists!$C$4)) -> Club House | BA11: =IF($G11="","",IF($I11=Lists!$B$4,Lists!$B$5,Lists!$C$5)) -> Mercantile | BB11: =IF($G11="","",IF($I11=Lists!$B$4,Lists!$B$6,Lists!$C$6)) -> Office | BC11: =IF($G11="","",IF($I11=Lists!$B$5,Lists!$B$7,Lists!$C$7)) -> Outbuilding | BD11: =IF($G11="","",IF($I11=Lists!$B$4,Lists!$B$8,Lists!$C$8)) -> Parking Garage | BE11: =IF($G11="","",IF($I11=Lists!$B$4,Lists!$B$9,Lists!$C$9)) -> Primary Residential Association | BF11: =IF($G11="","",IF($I11=Lists!$B$4,Lists!$B$10,Lists!$C$10)) -> Restaurant | BG11: =IF($G11="","",IF($I11=Lists!$B$4,Lists!$B$11,Lists!$C$11)) -> Secondary Residential Association | BH11: =IF($G11="","",IF($I11=Lists!$B$4,Lists!$B$12,Lists!$C$12)) -> Timeshare Association | BI11: =IF($G11="","",IF($I11=Lists!$B$4,Lists!$B$13,Lists!$C$13)) -> Detached Garages | BJ11: =IF($G11="","",IF($I11=Lists!$B$4,Lists!$B$14,Lists!$C$14)) -> Pool | BK11: =IF($G11="","",IF($I11=Lists!$B$4,Lists!$B$15,Lists!$C$15)) -> Street Lights | BL11: =IF($G11="","",IF($I11=Lists!$B$4,Lists!$B$16,Lists!$C$16)) -> Fence | BM11: =IF($G11="","",IF($I11=Lists!$B$4,Lists!$B$17,Lists!$C$17)) -> Docks | BN11: =IF($G11="","",IF($I11=Lists!$B$4,Lists!$B$18,Lists!$C$18)) -> Sign | BO11: =IF($G11="","",IF($I11=Lists!$B$4,Lists!$B$19,Lists!$C$19)) -> Other | BP11: =IF($G11="","",IF($I11=Lists!$B$4,Lists!$C$20,"")) | BQ11: =IF($G11="","",IF($I11=Lists!$B$4,Lists!$C$21,"")) | BR11: =IF($G11="","",IF($I11=Lists!$B$4,Lists!$C$22,"")) | BS11: =IF($G11="","",IF($I11=Lists!$B$4,Lists!$C$23,"")) | BT11: =IF($G11="","",IF($I11=Lists!$B$4,Lists!$C$24,"")) | BU11: =IF($G11="","",IF($I11=Lists!$B$4,Lists!$C$25,"")) | BV11: =IF($G11="","",IF($I11=Lists!$B$4,Lists!$C$26,"")) | BW11: =IF($G11="","",IF($I11=Lists!$B$4,Lists!$C$27,""))
F12: =IF(G12="","",VLOOKUP(TEXT(G12, "00000"),ZipCodeText,3,FALSE)) -> CT | G12: 6226 | P12: =IF(G12="","",SUM(M12:O12)) -> 0 | AZ12: =IF($G12="","",IF($I12=Lists!$B$4,Lists!$B$4,Lists!$C$4)) -> Club House | BA12: =IF($G12="","",IF($I12=Lists!$B$4,Lists!$B$5,Lists!$C$5)) -> Mercantile | BB12: =IF($G12="","",IF($I12=Lists!$B$4,Lists!$B$6,Lists!$C$6)) -> Office | BC12: =IF($G12="","",IF($I12=Lists!$B$5,Lists!$B$7,Lists!$C$7)) -> Outbuilding | BD12: =IF($G12="","",IF($I12=Lists!$B$4,Lists!$B$8,Lists!$C$8)) -> Parking Garage | BE12: =IF($G12="","",IF($I12=Lists!$B$4,Lists!$B$9,Lists!$C$9)) -> Primary Residential Association | BF12: =IF($G12="","",IF($I12=Lists!$B$4,Lists!$B$10,Lists!$C$10)) -> Restaurant | BG12: =IF($G12="","",IF($I12=Lists!$B$4,Lists!$B$11,Lists!$C$11)) -> Secondary Residential Association | BH12: =IF($G12="","",IF($I12=Lists!$B$4,Lists!$B$12,Lists!$C$12)) -> Timeshare Association | BI12: =IF($G12="","",IF($I12=Lists!$B$4,Lists!$B$13,Lists!$C$13)) -> Detached Garages | BJ12: =IF($G12="","",IF($I12=Lists!$B$4,Lists!$B$14,Lists!$C$14)) -> Pool | BK12: =IF($G12="","",IF($I12=Lists!$B$4,Lists!$B$15,Lists!$C$15)) -> Street Lights | BL12: =IF($G12="","",IF($I12=Lists!$B$4,Lists!$B$16,Lists!$C$16)) -> Fence | BM12: =IF($G12="","",IF($I12=Lists!$B$4,Lists!$B$17,Lists!$C$17)) -> Docks | BN12: =IF($G12="","",IF($I12=Lists!$B$4,Lists!$B$18,Lists!$C$18)) -> Sign | BO12: =IF($G12="","",IF($I12=Lists!$B$4,Lists!$B$19,Lists!$C$19)) -> Other | BP12: =IF($G12="","",IF($I12=Lists!$B$4,Lists!$C$20,"")) | BQ12: =IF($G12="","",IF($I12=Lists!$B$4,Lists!$C$21,"")) | BR12: =IF($G12="","",IF($I12=Lists!$B$4,Lists!$C$22,"")) | BS12: =IF($G12="","",IF($I12=Lists!$B$4,Lists!$C$23,"")) | BT12: =IF($G12="","",IF($I12=Lists!$B$4,Lists!$C$24,"")) | BU12: =IF($G12="","",IF($I12=Lists!$B$4,Lists!$C$25,"")) | BV12: =IF($G12="","",IF($I12=Lists!$B$4,Lists!$C$26,"")) | BW12: =IF($G12="","",IF($I12=Lists!$B$4,Lists!$C$27,""))
F13: =IF(G13="","",VLOOKUP(TEXT(G13, "00000"),ZipCodeText,3,FALSE)) -> CT | G13: 6226 | P13: =IF(G13="","",SUM(M13:O13)) -> 0 | AZ13: =IF($G13="","",IF($I13=Lists!$B$4,Lists!$B$4,Lists!$C$4)) -> Club House | BA13: =IF($G13="","",IF($I13=Lists!$B$4,Lists!$B$5,Lists!$C$5)) -> Mercantile | BB13: =IF($G13="","",IF($I13=Lists!$B$4,Lists!$B$6,Lists!$C$6)) -> Office | BC13: =IF($G13="","",IF($I13=Lists!$B$5,Lists!$B$7,Lists!$C$7)) -> Outbuilding | BD13: =IF($G13="","",IF($I13=Lists!$B$4,Lists!$B$8,Lists!$C$8)) -> Parking Garage | BE13: =IF($G13="","",IF($I13=Lists!$B$4,Lists!$B$9,Lists!$C$9)) -> Primary Residential Association | BF13: =IF($G13="","",IF($I13=Lists!$B$4,Lists!$B$10,Lists!$C$10)) -> Restaurant | BG13: =IF($G13="","",IF($I13=Lists!$B$4,Lists!$B$11,Lists!$C$11)) -> Secondary Residential Association | BH13: =IF($G13="","",IF($I13=Lists!$B$4,Lists!$B$12,Lists!$C$12)) -> Timeshare Association | BI13: =IF($G13="","",IF($I13=Lists!$B$4,Lists!$B$13,Lists!$C$13)) -> Detached Garages | BJ13: =IF($G13="","",IF($I13=Lists!$B$4,Lists!$B$14,Lists!$C$14)) -> Pool | BK13: =IF($G13="","",IF($I13=Lists!$B$4,Lists!$B$15,Lists!$C$15)) -> Street Lights | BL13: =IF($G13="","",IF($I13=Lists!$B$4,Lists!$B$16,Lists!$C$16)) -> Fence | BM13: =IF($G13="","",IF($I13=Lists!$B$4,Lists!$B$17,Lists!$C$17)) -> Docks | BN13: =IF($G13="","",IF($I13=Lists!$B$4,Lists!$B$18,Lists!$C$18)) -> Sign | BO13: =IF($G13="","",IF($I13=Lists!$B$4,Lists!$B$19,Lists!$C$19)) -> Other | BP13: =IF($G13="","",IF($I13=Lists!$B$4,Lists!$C$20,"")) | BQ13: =IF($G13="","",IF($I13=Lists!$B$4,Lists!$C$21,"")) | BR13: =IF($G13="","",IF($I13=Lists!$B$4,Lists!$C$22,"")) | BS13: =IF($G13="","",IF($I13=Lists!$B$4,Lists!$C$23,"")) | BT13: =IF($G13="","",IF($I13=Lists!$B$4,Lists!$C$24,"")) | BU13: =IF($G13="","",IF($I13=Lists!$B$4,Lists!$C$25,"")) | BV13: =IF($G13="","",IF($I13=Lists!$B$4,Lists!$C$26,"")) | BW13: =IF($G13="","",IF($I13=Lists!$B$4,Lists!$C$27,""))
F14: =IF(G14="","",VLOOKUP(TEXT(G14, "00000"),ZipCodeText,3,FALSE)) -> CT | G14: 6226 | P14: =IF(G14="","",SUM(M14:O14)) -> 0 | AZ14: =IF($G14="","",IF($I14=Lists!$B$4,Lists!$B$4,Lists!$C$4)) -> Club House | BA14: =IF($G14="","",IF($I14=Lists!$B$4,Lists!$B$5,Lists!$C$5)) -> Mercantile | BB14: =IF($G14="","",IF($I14=Lists!$B$4,Lists!$B$6,Lists!$C$6)) -> Office | BC14: =IF($G14="","",IF($I14=Lists!$B$5,Lists!$B$7,Lists!$C$7)) -> Outbuilding | BD14: =IF($G14="","",IF($I14=Lists!$B$4,Lists!$B$8,Lists!$C$8)) -> Parking Garage | BE14: =IF($G14="","",IF($I14=Lists!$B$4,Lists!$B$9,Lists!$C$9)) -> Primary Residential Association | BF14: =IF($G14="","",IF($I14=Lists!$B$4,Lists!$B$10,Lists!$C$10)) -> Restaurant | BG14: =IF($G14="","",IF($I14=Lists!$B$4,Lists!$B$11,Lists!$C$11)) -> Secondary Residential Association | BH14: =IF($G14="","",IF($I14=Lists!$B$4,Lists!$B$12,Lists!$C$12)) -> Timeshare Association | BI14: =IF($G14="","",IF($I14=Lists!$B$4,Lists!$B$13,Lists!$C$13)) -> Detached Garages | BJ14: =IF($G14="","",IF($I14=Lists!$B$4,Lists!$B$14,Lists!$C$14)) -> Pool | BK14: =IF($G14="","",IF($I14=Lists!$B$4,Lists!$B$15,Lists!$C$15)) -> Street Lights | BL14: =IF($G14="","",IF($I14=Lists!$B$4,Lists!$B$16,Lists!$C$16)) -> Fence | BM14: =IF($G14="","",IF($I14=Lists!$B$4,Lists!$B$17,Lists!$C$17)) -> Docks | BN14: =IF($G14="","",IF($I14=Lists!$B$4,Lists!$B$18,Lists!$C$18)) -> Sign | BO14: =IF($G14="","",IF($I14=Lists!$B$4,Lists!$B$19,Lists!$C$19)) -> Other | BP14: =IF($G14="","",IF($I14=Lists!$B$4,Lists!$C$20,"")) | BQ14: =IF($G14="","",IF($I14=Lists!$B$4,Lists!$C$21,"")) | BR14: =IF($G14="","",IF($I14=Lists!$B$4,Lists!$C$22,"")) | BS14: =IF($G14="","",IF($I14=Lists!$B$4,Lists!$C$23,"")) | BT14: =IF($G14="","",IF($I14=Lists!$B$4,Lists!$C$24,"")) | BU14: =IF($G14="","",IF($I14=Lists!$B$4,Lists!$C$25,"")) | BV14: =IF($G14="","",IF($I14=Lists!$B$4,Lists!$C$26,"")) | BW14: =IF($G14="","",IF($I14=Lists!$B$4,Lists!$C$27,""))
F15: =IF(G15="","",VLOOKUP(TEXT(G15, "00000"),ZipCodeText,3,FALSE)) -> CT | G15: 6226 | P15: =IF(G15="","",SUM(M15:O15)) -> 0 | AZ15: =IF($G15="","",IF($I15=Lists!$B$4,Lists!$B$4,Lists!$C$4)) -> Club House | BA15: =IF($G15="","",IF($I15=Lists!$B$4,Lists!$B$5,Lists!$C$5)) -> Mercantile | BB15: =IF($G15="","",IF($I15=Lists!$B$4,Lists!$B$6,Lists!$C$6)) -> Office | BC15: =IF($G15="","",IF($I15=Lists!$B$5,Lists!$B$7,Lists!$C$7)) -> Outbuilding | BD15: =IF($G15="","",IF($I15=Lists!$B$4,Lists!$B$8,Lists!$C$8)) -> Parking Garage | BE15: =IF($G15="","",IF($I15=Lists!$B$4,Lists!$B$9,Lists!$C$9)) -> Primary Residential Association | BF15: =IF($G15="","",IF($I15=Lists!$B$4,Lists!$B$10,Lists!$C$10)) -> Restaurant | BG15: =IF($G15="","",IF($I15=Lists!$B$4,Lists!$B$11,Lists!$C$11)) -> Secondary Residential Association | BH15: =IF($G15="","",IF($I15=Lists!$B$4,Lists!$B$12,Lists!$C$12)) -> Timeshare Association | BI15: =IF($G15="","",IF($I15=Lists!$B$4,Lists!$B$13,Lists!$C$13)) -> Detached Garages | BJ15: =IF($G15="","",IF($I15=Lists!$B$4,Lists!$B$14,Lists!$C$14)) -> Pool | BK15: =IF($G15="","",IF($I15=Lists!$B$4,Lists!$B$15,Lists!$C$15)) -> Street Lights | BL15: =IF($G15="","",IF($I15=Lists!$B$4,Lists!$B$16,Lists!$C$16)) -> Fence | BM15: =IF($G15="","",IF($I15=Lists!$B$4,Lists!$B$17,Lists!$C$17)) -> Docks | BN15: =IF($G15="","",IF($I15=Lists!$B$4,Lists!$B$18,Lists!$C$18)) -> Sign | BO15: =IF($G15="","",IF($I15=Lists!$B$4,Lists!$B$19,Lists!$C$19)) -> Other | BP15: =IF($G15="","",IF($I15=Lists!$B$4,Lists!$C$20,"")) | BQ15: =IF($G15="","",IF($I15=Lists!$B$4,Lists!$C$21,"")) | BR15: =IF($G15="","",IF($I15=Lists!$B$4,Lists!$C$22,"")) | BS15: =IF($G15="","",IF($I15=Lists!$B$4,Lists!$C$23,"")) | BT15: =IF($G15="","",IF($I15=Lists!$B$4,Lists!$C$24,"")) | BU15: =IF($G15="","",IF($I15=Lists!$B$4,Lists!$C$25,"")) | BV15: =IF($G15="","",IF($I15=Lists!$B$4,Lists!$C$26,"")) | BW15: =IF($G15="","",IF($I15=Lists!$B$4,Lists!$C$27,""))
F16: =IF(G16="","",VLOOKUP(TEXT(G16, "00000"),ZipCodeText,3,FALSE)) -> CT | G16: 6226 | P16: =IF(G16="","",SUM(M16:O16)) -> 0 | AZ16: =IF($G16="","",IF($I16=Lists!$B$4,Lists!$B$4,Lists!$C$4)) -> Club House | BA16: =IF($G16="","",IF($I16=Lists!$B$4,Lists!$B$5,Lists!$C$5)) -> Mercantile | BB16: =IF($G16="","",IF($I16=Lists!$B$4,Lists!$B$6,Lists!$C$6)) -> Office | BC16: =IF($G16="","",IF($I16=Lists!$B$5,Lists!$B$7,Lists!$C$7)) -> Outbuilding | BD16: =IF($G16="","",IF($I16=Lists!$B$4,Lists!$B$8,Lists!$C$8)) -> Parking Garage | BE16: =IF($G16="","",IF($I16=Lists!$B$4,Lists!$B$9,Lists!$C$9)) -> Primary Residential Association | BF16: =IF($G16="","",IF($I16=Lists!$B$4,Lists!$B$10,Lists!$C$10)) -> Restaurant | BG16: =IF($G16="","",IF($I16=Lists!$B$4,Lists!$B$11,Lists!$C$11)) -> Secondary Residential Association | BH16: =IF($G16="","",IF($I16=Lists!$B$4,Lists!$B$12,Lists!$C$12)) -> Timeshare Association | BI16: =IF($G16="","",IF($I16=Lists!$B$4,Lists!$B$13,Lists!$C$13)) -> Detached Garages | BJ16: =IF($G16="","",IF($I16=Lists!$B$4,Lists!$B$14,Lists!$C$14)) -> Pool | BK16: =IF($G16="","",IF($I16=Lists!$B$4,Lists!$B$15,Lists!$C$15)) -> Street Lights | BL16: =IF($G16="","",IF($I16=Lists!$B$4,Lists!$B$16,Lists!$C$16)) -> Fence | BM16: =IF($G16="","",IF($I16=Lists!$B$4,Lists!$B$17,Lists!$C$17)) -> Docks | BN16: =IF($G16="","",IF($I16=Lists!$B$4,Lists!$B$18,Lists!$C$18)) -> Sign | BO16: =IF($G16="","",IF($I16=Lists!$B$4,Lists!$B$19,Lists!$C$19)) -> Other | BP16: =IF($G16="","",IF($I16=Lists!$B$4,Lists!$C$20,"")) | BQ16: =IF($G16="","",IF($I16=Lists!$B$4,Lists!$C$21,"")) | BR16: =IF($G16="","",IF($I16=Lists!$B$4,Lists!$C$22,"")) | BS16: =IF($G16="","",IF($I16=Lists!$B$4,Lists!$C$23,"")) | BT16: =IF($G16="","",IF($I16=Lists!$B$4,Lists!$C$24,"")) | BU16: =IF($G16="","",IF($I16=Lists!$B$4,Lists!$C$25,"")) | BV16: =IF($G16="","",IF($I16=Lists!$B$4,Lists!$C$26,"")) | BW16: =IF($G16="","",IF($I16=Lists!$B$4,Lists!$C$27,""))
F17: =IF(G17="","",VLOOKUP(TEXT(G17, "00000"),ZipCodeText,3,FALSE)) -> CT | G17: 6226 | P17: =IF(G17="","",SUM(M17:O17)) -> 0 | AZ17: =IF($G17="","",IF($I17=Lists!$B$4,Lists!$B$4,Lists!$C$4)) -> Club House | BA17: =IF($G17="","",IF($I17=Lists!$B$4,Lists!$B$5,Lists!$C$5)) -> Mercantile | BB17: =IF($G17="","",IF($I17=Lists!$B$4,Lists!$B$6,Lists!$C$6)) -> Office | BC17: =IF($G17="","",IF($I17=Lists!$B$5,Lists!$B$7,Lists!$C$7)) -> Outbuilding | BD17: =IF($G17="","",IF($I17=Lists!$B$4,Lists!$B$8,Lists!$C$8)) -> Parking Garage | BE17: =IF($G17="","",IF($I17=Lists!$B$4,Lists!$B$9,Lists!$C$9)) -> Primary Residential Association | BF17: =IF($G17="","",IF($I17=Lists!$B$4,Lists!$B$10,Lists!$C$10)) -> Restaurant | BG17: =IF($G17="","",IF($I17=Lists!$B$4,Lists!$B$11,Lists!$C$11)) -> Secondary Residential Association | BH17: =IF($G17="","",IF($I17=Lists!$B$4,Lists!$B$12,Lists!$C$12)) -> Timeshare Association | BI17: =IF($G17="","",IF($I17=Lists!$B$4,Lists!$B$13,Lists!$C$13)) -> Detached Garages | BJ17: =IF($G17="","",IF($I17=Lists!$B$4,Lists!$B$14,Lists!$C$14)) -> Pool | BK17: =IF($G17="","",IF($I17=Lists!$B$4,Lists!$B$15,Lists!$C$15)) -> Street Lights | BL17: =IF($G17="","",IF($I17=Lists!$B$4,Lists!$B$16,Lists!$C$16)) -> Fence | BM17: =IF($G17="","",IF($I17=Lists!$B$4,Lists!$B$17,Lists!$C$17)) -> Docks | BN17: =IF($G17="","",IF($I17=Lists!$B$4,Lists!$B$18,Lists!$C$18)) -> Sign | BO17: =IF($G17="","",IF($I17=Lists!$B$4,Lists!$B$19,Lists!$C$19)) -> Other | BP17: =IF($G17="","",IF($I17=Lists!$B$4,Lists!$C$20,"")) | BQ17: =IF($G17="","",IF($I17=Lists!$B$4,Lists!$C$21,"")) | BR17: =IF($G17="","",IF($I17=Lists!$B$4,Lists!$C$22,"")) | BS17: =IF($G17="","",IF($I17=Lists!$B$4,Lists!$C$23,"")) | BT17: =IF($G17="","",IF($I17=Lists!$B$4,Lists!$C$24,"")) | BU17: =IF($G17="","",IF($I17=Lists!$B$4,Lists!$C$25,"")) | BV17: =IF($G17="","",IF($I17=Lists!$B$4,Lists!$C$26,"")) | BW17: =IF($G17="","",IF($I17=Lists!$B$4,Lists!$C$27,""))
... F302: =IF(G302="","",VLOOKUP(TEXT(G302, "00000"),ZipCodeText,3,FALSE)) -> CT | G302: 6226 | P302: =IF(G302="","",SUM(M302:O302)) -> 0 | AZ302: =IF($G302="","",IF($I302=Lists!$B$4,Lists!$B$4,Lists!$C$4)) -> Club House | BA302: =IF($G302="","",IF($I302=Lists!$B$4,Lists!$B$5,Lists!$C$5)) -> Mercantile | BB302: =IF($G302="","",IF($I302=Lists!$B$4,Lists!$B$6,Lists!$C$6)) -> Office | BC302: =IF($G302="","",IF($I302=Lists!$B$5,Lists!$B$7,Lists!$C$7)) -> Outbuilding | BD302: =IF($G302="","",IF($I302=Lists!$B$4,Lists!$B$8,Lists!$C$8)) -> Parking Garage | BE302: =IF($G302="","",IF($I302=Lists!$B$4,Lists!$B$9,Lists!$C$9)) -> Primary Residential Association | BF302: =IF($G302="","",IF($I302=Lists!$B$4,Lists!$B$10,Lists!$C$10)) -> Restaurant | BG302: =IF($G302="","",IF($I302=Lists!$B$4,Lists!$B$11,Lists!$C$11)) -> Secondary Residential Association | BH302: =IF($G302="","",IF($I302=Lists!$B$4,Lists!$B$12,Lists!$C$12)) -> Timeshare Association | BI302: =IF($G302="","",IF($I302=Lists!$B$4,Lists!$B$13,Lists!$C$13)) -> Detached Garages | BJ302: =IF($G302="","",IF($I302=Lists!$B$4,Lists!$B$14,Lists!$C$14)) -> Pool | BK302: =IF($G302="","",IF($I302=Lists!$B$4,Lists!$B$15,Lists!$C$15)) -> Street Lights | BL302: =IF($G302="","",IF($I302=Lists!$B$4,Lists!$B$16,Lists!$C$16)) -> Fence | BM302: =IF($G302="","",IF($I302=Lists!$B$4,Lists!$B$17,Lists!$C$17)) -> Docks | BN302: =IF($G302="","",IF($I302=Lists!$B$4,Lists!$B$18,Lists!$C$18)) -> Sign | BO302: =IF($G302="","",IF($I302=Lists!$B$4,Lists!$B$19,Lists!$C$19)) -> Other | BP302: =IF($G302="","",IF($I302=Lists!$B$4,Lists!$C$20,"")) | BQ302: =IF($G302="","",IF($I302=Lists!$B$4,Lists!$C$21,"")) | BR302: =IF($G302="","",IF($I302=Lists!$B$4,Lists!$C$22,"")) | BS302: =IF($G302="","",IF($I302=Lists!$B$4,Lists!$C$23,"")) | BT302: =IF($G302="","",IF($I302=Lists!$B$4,Lists!$C$24,"")) | BU302: =IF($G302="","",IF($I302=Lists!$B$4,Lists!$C$25,"")) | BV302: =IF($G302="","",IF($I302=Lists!$B$4,Lists!$C$26,"")) | BW302: =IF($G302="","",IF($I302=Lists!$B$4,Lists!$C$27,""))

Sheet Lists
B1: Use Class | C1: Use Class | F1: Construction Type | H1: Protection Class | I1: Roof Type | J1: Roof Shape | K1: Age of Plumbing | L1: Circuits | M1: Wiring Type | N1: Wiring Update
A2: Ownership | B2: Apartments | C2: Condo Association | F2: Frame | H2: 1 | I2: Asphalt / Composition Shingle | J2: 1 - Gable | K2: Unknown / Varies per Unit | L2: Circuit Breakers | M2: Copper | N2: N/A
F3: Joisted Masonry | H3: 2 | I3: Asphalt / Architectural Shingle | J3: 2 - Hipped | K3: <5 Years | L3: Fuses | M3: Aluminum | N3: COPALUM
A4: Apartment | B4: Affordable | C4: Club House | F4: Masonry Non-Conbustible | H4: 3 | I4: Metal | J4: 3 - A - Frame | K4: 5-10 Years | L4: Stablok Circuit Breakers by Fed Pacific | M4: Knob & Tube | N4: AlumiConn
A5: Condo Association - Condos | B5: No Other Classification | C5: Mercantile | F5: Masonry Veneer | H5: 4 | I5: Concrete Tile | J5: 4 - Mansard | K5: >10 Years | L5: Other | M5: Other | N5: Other
A6: Condo Association - Townhomes | B6: Club House | C6: Office | F6: Non-Combustible | H6: 5 | I6: Clay Tile | J6: 5 - Gambrel
B7: Cooperative | C7: Outbuilding | F7: Reinforced Concrete | H7: 6 | I7: Wood Shake
B8: Dwelling 1-4 | C8: Parking Garage | H8: 7 | I8: Flat-tar & gravel
B9: Dwelling 5+ | C9: Primary Residential Association | H9: 8 | I9: Flat-membrane / #ply
B10: Mercantile | C10: Restaurant | H10: 9
B11: Office | C11: Secondary Residential Association | H11: 10
B12: Outbuilding | C12: Timeshare Association
B13: Parking Garage | C13: Detached Garages
B14: Public | C14: Pool
B15: Rental Condos | C15: Street Lights
B16: Restaurant | C16: Fence
B17: Rowhouse | C17: Docks
B18: Senior | C18: Sign
B19: Student Apartment | C19: Other
B20: Student Dwelling
B21: Detached Garages
B22: Pool
B23: Street Lights
B24: Fence
B25: Docks
B26: Sign
B27: Other
A31: Age Of Electrical | B31: Heating Type | C31: Age of HVAC | D31: Under Renovation | E31: Interior Coverage | F31: Condo % Leased | G31: % Occupied | H31: Sprinkler System | I31: Smoke Detectors | J31: Smoking Options | K31: Stovetop Options | L31: Freezer Sensors | M31: Central Fire Alarm | N31: Surveillance Camera | O31: Sprinkler Leakage Exclusion | P31: Location Blanket Limit | Q31: Loss Settlement | R31: Hail Claims | S31: Coastal <= 2500 Feet
A32: Unknown / Varies per Unit | B32: Forced Air | C32: Unknown / Varies per Unit | D32: No | E32: N/A - Apartments | F32: 0-5% | G32: <33% | H32: 100% System 13 | I32: None | J32: None | K32: N | L32: N | M32: No | N32: No | O32: No | P32: Yes | Q32: RC | R32: No | S32: No
A33: <5 Years | B33: Wall Furnace | C33: <5 Years | D33: Yes | E33: Bare Walls | F33: 5-10% | G33: 33%-80% | H33: None | I33: Battery | J33: Smoke Free | K33: Y - Insur-Fi | L33: Y - Insur-Fi | M33: Yes | N33: Yes | O33: Yes | P33: No | Q33: ACV | R33: Yes, not Settled | S33: Yes
A34: 5-10 Years | B34: Floor Furnace | C34: 5-10 Years | E34: All In | F34: 10-15% | G34: >80% | H34: Partial | I34: Hardwired | J34: Smoking Area | K34: Y - Non-Insur-Fi | L34: Y - Non-Insur-Fi | R34: Yes, Settled
A35: >10 Years | B35: Boiler | C35: >10 Years | E35: Original Specifications | F35: 15-20% | I35: Both
B36: Electric Heater | E36: Modified Original Specifications | F36: 20-25%
B37: Gas Heater | F37: 25-30%
B38: Oil | F38: 30-35%
B39: Fireplace | F39: 35-50%
B40: Woodburning or Pellet stove | F40: 50-100%
B41: Other | F41: 100%

Sheet ZipCodes
A1: zip | B1: City | C1: State
A2: 36507 | B2: Bay Minette | C2: AL
A3: 36511 | B3: Bon Secour | C3: AL
A4: 36526 | B4: Daphne | C4: AL
A5: 36527 | B5: Spanish Fort | C5: AL
A6: 36530 | B6: Elberta | C6: AL
A7: 36532 | B7: Fairhope | C7: AL
A8: 36533 | B8: Fairhope | C8: AL
A9: 36535 | B9: Foley | C9: AL
A10: 36536 | B10: Foley | C10: AL
A11: 36542 | B11: Gulf Shores | C11: AL
A12: 36547 | B12: Gulf Shores | C12: AL
A13: 36549 | B13: Lillian | C13: AL
A14: 36551 | B14: Loxley | C14: AL
A15: 36555 | B15: Magnolia Springs | C15: AL
A16: 36559 | B16: Montrose | C16: AL
A17: 36561 | B17: Orange Beach | C17: AL
A18: 36564 | B18: Point Clear | C18: AL
A19: 36567 | B19: Robertsdale | C19: AL
A20: 36574 | B20: Seminole | C20: AL
A21: 36576 | B21: Silverhill | C21: AL
A22: 36577 | B22: Spanish Fort | C22: AL
A23: 36578 | B23: Stapleton | C23: AL
A24: 36580 | B24: Summerdale | C24: AL
A25: 35005 | B25: Adamsville | C25: AL
A26: 35006 | B26: Adger | C26: AL
... A55: 35181 | B55: Watson | C55: AL
A56: 35201 | B56: Birmingham | C56: AL
A57: 35202 | B57: Birmingham | C57: AL
A58: 35203 | B58: Birmingham | C58: AL
A59: 35204 | B59: Birmingham | C59: AL
A60: 35205 | B60: Birmingham | C60: AL
A61: 35206 | B61: Birmingham | C61: AL
A62: 35207 | B62: Birmingham | C62: AL
A63: 35208 | B63: Birmingham | C63: AL
A64: 35209 | B64: Birmingham | C64: AL
A65: 35210 | B65: Birmingham | C65: AL
A66: 35211 | B66: Birmingham | C66: AL
A67: 35212 | B67: Birmingham | C67: AL
... A2225: 80516 | B2225: Erie | C2225: CO
...
